Workbook

Sheet tips dataset
A1: sex | B1: smoker | C1: day | D1: time | E1: size | F1: total_bill | G1: tip
A2: Female | B2: Yes | C2: Sat | D2: Dinner | E2: 1 | F2: 3.07 | G2: 1
A3: Female | B3: Yes | C3: Fri | D3: Dinner | E3: 2 | F3: 5.75 | G3: 1 | J3: sex | K3: Gender of the customer
A4: Female | B4: No | C4: Sat | D4: Dinner | E4: 1 | F4: 7.25 | G4: 1 | J4: smoker | K4: Indicates if the customer is a smoker or not
A5: Male | B5: Yes | C5: Sun | D5: Dinner | E5: 2 | F5: 7.25 | G5: 5.15 | J5: day | K5: Day of the restaurant visit
A6: Male | B6: No | C6: Thur | D6: Lunch | E6: 2 | F6: 7.51 | G6: 2 | J6: time | K6: Indicates whether the tip was for lunch or dinner
A7: Male | B7: No | C7: Thur | D7: Lunch | E7: 2 | F7: 7.56 | G7: 1.44 | J7: size | K7: Number of members dining
A8: Male | B8: Yes | C8: Sat | D8: Dinner | E8: 2 | F8: 7.74 | G8: 1.44 | J8: total bill | K8: Bill amount in USD
A9: Female | B9: No | C9: Thur | D9: Lunch | E9: 2 | F9: 8.35 | G9: 1.5 | J9: tip | K9: Tip amount in USD
A10: Female | B10: No | C10: Thur | D10: Lunch | E10: 2 | F10: 8.51 | G10: 1.25
A11: Male | B11: No | C11: Thur | D11: Lunch | E11: 2 | F11: 8.52 | G11: 1.48
A12: Male | B12: Yes | C12: Fri | D12: Lunch | E12: 1 | F12: 8.58 | G12: 1.92
A13: Male | B13: No | C13: Sun | D13: Dinner | E13: 2 | F13: 8.77 | G13: 2
A14: Male | B14: No | C14: Sat | D14: Dinner | E14: 2 | F14: 9.55 | G14: 1.45
A15: Female | B15: Yes | C15: Sun | D15: Dinner | E15: 2 | F15: 9.6 | G15: 4
A16: Male | B16: No | C16: Sun | D16: Dinner | E16: 2 | F16: 9.68 | G16: 1.32
A17: Male | B17: No | C17: Thur | D17: Lunch | E17: 2 | F17: 9.78 | G17: 1.73
A18: Male | B18: No | C18: Sun | D18: Dinner | E18: 2 | F18: 9.94 | G18: 1.56
A19: Female | B19: No | C19: Thur | D19: Lunch | E19: 1 | F19: 10.07 | G19: 1.83
A20: Male | B20: No | C20: Sat | D20: Dinner | E20: 2 | F20: 10.07 | G20: 1.25
A21: Female | B21: Yes | C21: Fri | D21: Lunch | E21: 2 | F21: 10.09 | G21: 2
... A244: Male | B244: Yes | C244: Sat | D244: Dinner | E244: 3 | F244: 50.81 | G244: 10

Sheet Data 
A1: Male | B1: Female | C1: Smoker Yes | D1: smoker No | E1: Sat | F1: fri | G1: Sun | H1: Lunch | I1: Dinner | J1: size | K1: total_bill | L1: tip | M1: tip % | N1: Per person Bill | O1: Per person tip | P1: thur | Q1: Cust value
A2: =IF('tips dataset'!$A2="Male",1,0) -> 0 | B2: =IF('tips dataset'!$A2="Female",1,0) -> 1 | C2: =IF('tips dataset'!$B2="Yes",1,0) -> 1 | D2: =IF('tips dataset'!$B2="No",1,0) -> 0 | E2: =IF('tips dataset'!$C2="Sat",1,0) -> 1 | F2: =IF('tips dataset'!$C2="fri",1,0) -> 0 | G2: =IF('tips dataset'!$C2="Sun",1,0) -> 0 | H2: =IF('tips dataset'!$D2="Lunch",1,0) -> 0 | I2: =IF('tips dataset'!$D2="Dinner",1,0) -> 1 | J2: ='tips dataset'!$E2 -> 1 | K2: 16.99 | L2: 1.01 | M2: =L2/K2 -> 0.059446733 | N2: =K2/J2 -> 16.99 | O2: =L2/J2 -> 1.01 | P2: =IF('tips dataset'!$C2="thur",1,0) -> 0 | Q2: =IF(K2<15,"Low",IF(K2<25,"Medium",IF(K2<35,"High","Premium"))) -> Medium
A3: =IF('tips dataset'!$A3="Male",1,0) -> 0 | B3: =IF('tips dataset'!$A3="Female",1,0) -> 1 | C3: =IF('tips dataset'!$B3="Yes",1,0) -> 1 | D3: =IF('tips dataset'!$B3="No",1,0) -> 0 | E3: =IF('tips dataset'!$C3="Sat",1,0) -> 0 | F3: =IF('tips dataset'!$C3="fri",1,0) -> 1 | G3: =IF('tips dataset'!$C3="Sun",1,0) -> 0 | H3: =IF('tips dataset'!$D3="Lunch",1,0) -> 0 | I3: =IF('tips dataset'!$D3="Dinner",1,0) -> 1 | J3: ='tips dataset'!$E3 -> 2 | K3: 10.34 | L3: 1.66 | M3: =L3/K3 -> 0.16054159 | N3: =K3/J3 -> 5.17 | O3: =L3/J3 -> 0.83 | P3: =IF('tips dataset'!$C3="thur",1,0) -> 0 | Q3: =IF(K3<15,"Low",IF(K3<25,"Medium",IF(K3<35,"High","Premium"))) -> Low | V3: sex | W3: Gender of the customer
A4: =IF('tips dataset'!$A4="Male",1,0) -> 0 | B4: =IF('tips dataset'!$A4="Female",1,0) -> 1 | C4: =IF('tips dataset'!$B4="Yes",1,0) -> 0 | D4: =IF('tips dataset'!$B4="No",1,0) -> 1 | E4: =IF('tips dataset'!$C4="Sat",1,0) -> 1 | F4: =IF('tips dataset'!$C4="fri",1,0) -> 0 | G4: =IF('tips dataset'!$C4="Sun",1,0) -> 0 | H4: =IF('tips dataset'!$D4="Lunch",1,0) -> 0 | I4: =IF('tips dataset'!$D4="Dinner",1,0) -> 1 | J4: ='tips dataset'!$E4 -> 1 | K4: 21.01 | L4: 3.5 | M4: =L4/K4 -> 0.16658734 | N4: =K4/J4 -> 21.01 | O4: =L4/J4 -> 3.5 | P4: =IF('tips dataset'!$C4="thur",1,0) -> 0 | Q4: =IF(K4<15,"Low",IF(K4<25,"Medium",IF(K4<35,"High","Premium"))) -> Medium | V4: smoker | W4: Indicates if the customer is a smoker or not
A5: =IF('tips dataset'!$A5="Male",1,0) -> 1 | B5: =IF('tips dataset'!$A5="Female",1,0) -> 0 | C5: =IF('tips dataset'!$B5="Yes",1,0) -> 1 | D5: =IF('tips dataset'!$B5="No",1,0) -> 0 | E5: =IF('tips dataset'!$C5="Sat",1,0) -> 0 | F5: =IF('tips dataset'!$C5="fri",1,0) -> 0 | G5: =IF('tips dataset'!$C5="Sun",1,0) -> 1 | H5: =IF('tips dataset'!$D5="Lunch",1,0) -> 0 | I5: =IF('tips dataset'!$D5="Dinner",1,0) -> 1 | J5: ='tips dataset'!$E5 -> 2 | K5: 23.68 | L5: 3.31 | M5: =L5/K5 -> 0.13978041 | N5: =K5/J5 -> 11.84 | O5: =L5/J5 -> 1.655 | P5: =IF('tips dataset'!$C5="thur",1,0) -> 0 | Q5: =IF(K5<15,"Low",IF(K5<25,"Medium",IF(K5<35,"High","Premium"))) -> Medium | V5: day | W5: Day of the restaurant visit
A6: =IF('tips dataset'!$A6="Male",1,0) -> 1 | B6: =IF('tips dataset'!$A6="Female",1,0) -> 0 | C6: =IF('tips dataset'!$B6="Yes",1,0) -> 0 | D6: =IF('tips dataset'!$B6="No",1,0) -> 1 | E6: =IF('tips dataset'!$C6="Sat",1,0) -> 0 | F6: =IF('tips dataset'!$C6="fri",1,0) -> 0 | G6: =IF('tips dataset'!$C6="Sun",1,0) -> 0 | H6: =IF('tips dataset'!$D6="Lunch",1,0) -> 1 | I6: =IF('tips dataset'!$D6="Dinner",1,0) -> 0 | J6: ='tips dataset'!$E6 -> 2 | K6: 24.59 | L6: 3.61 | M6: =L6/K6 -> 0.14680765 | N6: =K6/J6 -> 12.295 | O6: =L6/J6 -> 1.805 | P6: =IF('tips dataset'!$C6="thur",1,0) -> 1 | Q6: =IF(K6<15,"Low",IF(K6<25,"Medium",IF(K6<35,"High","Premium"))) -> Medium | V6: time | W6: Indicates whether the tip was for lunch or dinner
A7: =IF('tips dataset'!$A7="Male",1,0) -> 1 | B7: =IF('tips dataset'!$A7="Female",1,0) -> 0 | C7: =IF('tips dataset'!$B7="Yes",1,0) -> 0 | D7: =IF('tips dataset'!$B7="No",1,0) -> 1 | E7: =IF('tips dataset'!$C7="Sat",1,0) -> 0 | F7: =IF('tips dataset'!$C7="fri",1,0) -> 0 | G7: =IF('tips dataset'!$C7="Sun",1,0) -> 0 | H7: =IF('tips dataset'!$D7="Lunch",1,0) -> 1 | I7: =IF('tips dataset'!$D7="Dinner",1,0) -> 0 | J7: ='tips dataset'!$E7 -> 2 | K7: 25.29 | L7: 4.71 | M7: =L7/K7 -> 0.18623962 | N7: =K7/J7 -> 12.645 | O7: =L7/J7 -> 2.355 | P7: =IF('tips dataset'!$C7="thur",1,0) -> 1 | Q7: =IF(K7<15,"Low",IF(K7<25,"Medium",IF(K7<35,"High","Premium"))) -> High | V7: size | W7: Number of members dining
A8: =IF('tips dataset'!$A8="Male",1,0) -> 1 | B8: =IF('tips dataset'!$A8="Female",1,0) -> 0 | C8: =IF('tips dataset'!$B8="Yes",1,0) -> 1 | D8: =IF('tips dataset'!$B8="No",1,0) -> 0 | E8: =IF('tips dataset'!$C8="Sat",1,0) -> 1 | F8: =IF('tips dataset'!$C8="fri",1,0) -> 0 | G8: =IF('tips dataset'!$C8="Sun",1,0) -> 0 | H8: =IF('tips dataset'!$D8="Lunch",1,0) -> 0 | I8: =IF('tips dataset'!$D8="Dinner",1,0) -> 1 | J8: ='tips dataset'!$E8 -> 2 | K8: 8.77 | L8: 2 | M8: =L8/K8 -> 0.22805017 | N8: =K8/J8 -> 4.385 | O8: =L8/J8 -> 1 | P8: =IF('tips dataset'!$C8="thur",1,0) -> 0 | Q8: =IF(K8<15,"Low",IF(K8<25,"Medium",IF(K8<35,"High","Premium"))) -> Low | V8: total bill | W8: Bill amount in USD
A9: =IF('tips dataset'!$A9="Male",1,0) -> 0 | B9: =IF('tips dataset'!$A9="Female",1,0) -> 1 | C9: =IF('tips dataset'!$B9="Yes",1,0) -> 0 | D9: =IF('tips dataset'!$B9="No",1,0) -> 1 | E9: =IF('tips dataset'!$C9="Sat",1,0) -> 0 | F9: =IF('tips dataset'!$C9="fri",1,0) -> 0 | G9: =IF('tips dataset'!$C9="Sun",1,0) -> 0 | H9: =IF('tips dataset'!$D9="Lunch",1,0) -> 1 | I9: =IF('tips dataset'!$D9="Dinner",1,0) -> 0 | J9: ='tips dataset'!$E9 -> 2 | K9: 26.88 | L9: 3.12 | M9: =L9/K9 -> 0.11607143 | N9: =K9/J9 -> 13.44 | O9: =L9/J9 -> 1.56 | P9: =IF('tips dataset'!$C9="thur",1,0) -> 1 | Q9: =IF(K9<15,"Low",IF(K9<25,"Medium",IF(K9<35,"High","Premium"))) -> High | V9: tip | W9: Tip amount in USD
A10: =IF('tips dataset'!$A10="Male",1,0) -> 0 | B10: =IF('tips dataset'!$A10="Female",1,0) -> 1 | C10: =IF('tips dataset'!$B10="Yes",1,0) -> 0 | D10: =IF('tips dataset'!$B10="No",1,0) -> 1 | E10: =IF('tips dataset'!$C10="Sat",1,0) -> 0 | F10: =IF('tips dataset'!$C10="fri",1,0) -> 0 | G10: =IF('tips dataset'!$C10="Sun",1,0) -> 0 | H10: =IF('tips dataset'!$D10="Lunch",1,0) -> 1 | I10: =IF('tips dataset'!$D10="Dinner",1,0) -> 0 | J10: ='tips dataset'!$E10 -> 2 | K10: 15.04 | L10: 1.96 | M10: =L10/K10 -> 0.13031915 | N10: =K10/J10 -> 7.52 | O10: =L10/J10 -> 0.98 | P10: =IF('tips dataset'!$C10="thur",1,0) -> 1 | Q10: =IF(K10<15,"Low",IF(K10<25,"Medium",IF(K10<35,"High","Premium"))) -> Medium | V10: Tip % | W10: Tip/total bill
A11: =IF('tips dataset'!$A11="Male",1,0) -> 1 | B11: =IF('tips dataset'!$A11="Female",1,0) -> 0 | C11: =IF('tips dataset'!$B11="Yes",1,0) -> 0 | D11: =IF('tips dataset'!$B11="No",1,0) -> 1 | E11: =IF('tips dataset'!$C11="Sat",1,0) -> 0 | F11: =IF('tips dataset'!$C11="fri",1,0) -> 0 | G11: =IF('tips dataset'!$C11="Sun",1,0) -> 0 | H11: =IF('tips dataset'!$D11="Lunch",1,0) -> 1 | I11: =IF('tips dataset'!$D11="Dinner",1,0) -> 0 | J11: ='tips dataset'!$E11 -> 2 | K11: 14.78 | L11: 3.23 | M11: =L11/K11 -> 0.21853857 | N11: =K11/J11 -> 7.39 | O11: =L11/J11 -> 1.615 | P11: =IF('tips dataset'!$C11="thur",1,0) -> 1 | Q11: =IF(K11<15,"Low",IF(K11<25,"Medium",IF(K11<35,"High","Premium"))) -> Low | V11: per person bill | W11: Total bill/size
A12: =IF('tips dataset'!$A12="Male",1,0) -> 1 | B12: =IF('tips dataset'!$A12="Female",1,0) -> 0 | C12: =IF('tips dataset'!$B12="Yes",1,0) -> 1 | D12: =IF('tips dataset'!$B12="No",1,0) -> 0 | E12: =IF('tips dataset'!$C12="Sat",1,0) -> 0 | F12: =IF('tips dataset'!$C12="fri",1,0) -> 1 | G12: =IF('tips dataset'!$C12="Sun",1,0) -> 0 | H12: =IF('tips dataset'!$D12="Lunch",1,0) -> 1 | I12: =IF('tips dataset'!$D12="Dinner",1,0) -> 0 | J12: ='tips dataset'!$E12 -> 1 | K12: 10.27 | L12: 1.71 | M12: =L12/K12 -> 0.16650438 | N12: =K12/J12 -> 10.27 | O12: =L12/J12 -> 1.71 | P12: =IF('tips dataset'!$C12="thur",1,0) -> 0 | Q12: =IF(K12<15,"Low",IF(K12<25,"Medium",IF(K12<35,"High","Premium"))) -> Low | V12: per sperson tip | W12: tip/size
A13: =IF('tips dataset'!$A13="Male",1,0) -> 1 | B13: =IF('tips dataset'!$A13="Female",1,0) -> 0 | C13: =IF('tips dataset'!$B13="Yes",1,0) -> 0 | D13: =IF('tips dataset'!$B13="No",1,0) -> 1 | E13: =IF('tips dataset'!$C13="Sat",1,0) -> 0 | F13: =IF('tips dataset'!$C13="fri",1,0) -> 0 | G13: =IF('tips dataset'!$C13="Sun",1,0) -> 1 | H13: =IF('tips dataset'!$D13="Lunch",1,0) -> 0 | I13: =IF('tips dataset'!$D13="Dinner",1,0) -> 1 | J13: ='tips dataset'!$E13 -> 2 | K13: 35.26 | L13: 5 | M13: =L13/K13 -> 0.14180374 | N13: =K13/J13 -> 17.63 | O13: =L13/J13 -> 2.5 | P13: =IF('tips dataset'!$C13="thur",1,0) -> 0 | Q13: =IF(K13<15,"Low",IF(K13<25,"Medium",IF(K13<35,"High","Premium"))) -> Premium
A14: =IF('tips dataset'!$A14="Male",1,0) -> 1 | B14: =IF('tips dataset'!$A14="Female",1,0) -> 0 | C14: =IF('tips dataset'!$B14="Yes",1,0) -> 0 | D14: =IF('tips dataset'!$B14="No",1,0) -> 1 | E14: =IF('tips dataset'!$C14="Sat",1,0) -> 1 | F14: =IF('tips dataset'!$C14="fri",1,0) -> 0 | G14: =IF('tips dataset'!$C14="Sun",1,0) -> 0 | H14: =IF('tips dataset'!$D14="Lunch",1,0) -> 0 | I14: =IF('tips dataset'!$D14="Dinner",1,0) -> 1 | J14: ='tips dataset'!$E14 -> 2 | K14: 15.42 | L14: 1.57 | M14: =L14/K14 -> 0.10181582 | N14: =K14/J14 -> 7.71 | O14: =L14/J14 -> 0.785 | P14: =IF('tips dataset'!$C14="thur",1,0) -> 0 | Q14: =IF(K14<15,"Low",IF(K14<25,"Medium",IF(K14<35,"High","Premium"))) -> Medium
A15: =IF('tips dataset'!$A15="Male",1,0) -> 0 | B15: =IF('tips dataset'!$A15="Female",1,0) -> 1 | C15: =IF('tips dataset'!$B15="Yes",1,0) -> 1 | D15: =IF('tips dataset'!$B15="No",1,0) -> 0 | E15: =IF('tips dataset'!$C15="Sat",1,0) -> 0 | F15: =IF('tips dataset'!$C15="fri",1,0) -> 0 | G15: =IF('tips dataset'!$C15="Sun",1,0) -> 1 | H15: =IF('tips dataset'!$D15="Lunch",1,0) -> 0 | I15: =IF('tips dataset'!$D15="Dinner",1,0) -> 1 | J15: ='tips dataset'!$E15 -> 2 | K15: 18.43 | L15: 3 | M15: =L15/K15 -> 0.16277808 | N15: =K15/J15 -> 9.215 | O15: =L15/J15 -> 1.5 | P15: =IF('tips dataset'!$C15="thur",1,0) -> 0 | Q15: =IF(K15<15,"Low",IF(K15<25,"Medium",IF(K15<35,"High","Premium"))) -> Medium
A16: =IF('tips dataset'!$A16="Male",1,0) -> 1 | B16: =IF('tips dataset'!$A16="Female",1,0) -> 0 | C16: =IF('tips dataset'!$B16="Yes",1,0) -> 0 | D16: =IF('tips dataset'!$B16="No",1,0) -> 1 | E16: =IF('tips dataset'!$C16="Sat",1,0) -> 0 | F16: =IF('tips dataset'!$C16="fri",1,0) -> 0 | G16: =IF('tips dataset'!$C16="Sun",1,0) -> 1 | H16: =IF('tips dataset'!$D16="Lunch",1,0) -> 0 | I16: =IF('tips dataset'!$D16="Dinner",1,0) -> 1 | J16: ='tips dataset'!$E16 -> 2 | K16: 14.83 | L16: 3.02 | M16: =L16/K16 -> 0.20364127 | N16: =K16/J16 -> 7.415 | O16: =L16/J16 -> 1.51 | P16: =IF('tips dataset'!$C16="thur",1,0) -> 0 | Q16: =IF(K16<15,"Low",IF(K16<25,"Medium",IF(K16<35,"High","Premium"))) -> Low
A17: =IF('tips dataset'!$A17="Male",1,0) -> 1 | B17: =IF('tips dataset'!$A17="Female",1,0) -> 0 | C17: =IF('tips dataset'!$B17="Yes",1,0) -> 0 | D17: =IF('tips dataset'!$B17="No",1,0) -> 1 | E17: =IF('tips dataset'!$C17="Sat",1,0) -> 0 | F17: =IF('tips dataset'!$C17="fri",1,0) -> 0 | G17: =IF('tips dataset'!$C17="Sun",1,0) -> 0 | H17: =IF('tips dataset'!$D17="Lunch",1,0) -> 1 | I17: =IF('tips dataset'!$D17="Dinner",1,0) -> 0 | J17: ='tips dataset'!$E17 -> 2 | K17: 21.58 | L17: 3.92 | M17: =L17/K17 -> 0.18164968 | N17: =K17/J17 -> 10.79 | O17: =L17/J17 -> 1.96 | P17: =IF('tips dataset'!$C17="thur",1,0) -> 1 | Q17: =IF(K17<15,"Low",IF(K17<25,"Medium",IF(K17<35,"High","Premium"))) -> Medium
A18: =IF('tips dataset'!$A18="Male",1,0) -> 1 | B18: =IF('tips dataset'!$A18="Female",1,0) -> 0 | C18: =IF('tips dataset'!$B18="Yes",1,0) -> 0 | D18: =IF('tips dataset'!$B18="No",1,0) -> 1 | E18: =IF('tips dataset'!$C18="Sat",1,0) -> 0 | F18: =IF('tips dataset'!$C18="fri",1,0) -> 0 | G18: =IF('tips dataset'!$C18="Sun",1,0) -> 1 | H18: =IF('tips dataset'!$D18="Lunch",1,0) -> 0 | I18: =IF('tips dataset'!$D18="Dinner",1,0) -> 1 | J18: ='tips dataset'!$E18 -> 2 | K18: 10.33 | L18: 1.67 | M18: =L18/K18 -> 0.16166505 | N18: =K18/J18 -> 5.165 | O18: =L18/J18 -> 0.835 | P18: =IF('tips dataset'!$C18="thur",1,0) -> 0 | Q18: =IF(K18<15,"Low",IF(K18<25,"Medium",IF(K18<35,"High","Premium"))) -> Low
A19: =IF('tips dataset'!$A19="Male",1,0) -> 0 | B19: =IF('tips dataset'!$A19="Female",1,0) -> 1 | C19: =IF('tips dataset'!$B19="Yes",1,0) -> 0 | D19: =IF('tips dataset'!$B19="No",1,0) -> 1 | E19: =IF('tips dataset'!$C19="Sat",1,0) -> 0 | F19: =IF('tips dataset'!$C19="fri",1,0) -> 0 | G19: =IF('tips dataset'!$C19="Sun",1,0) -> 0 | H19: =IF('tips dataset'!$D19="Lunch",1,0) -> 1 | I19: =IF('tips dataset'!$D19="Dinner",1,0) -> 0 | J19: ='tips dataset'!$E19 -> 1 | K19: 16.29 | L19: 3.71 | M19: =L19/K19 -> 0.22774708 | N19: =K19/J19 -> 16.29 | O19: =L19/J19 -> 3.71 | P19: =IF('tips dataset'!$C19="thur",1,0) -> 1 | Q19: =IF(K19<15,"Low",IF(K19<25,"Medium",IF(K19<35,"High","Premium"))) -> Medium
A20: =IF('tips dataset'!$A20="Male",1,0) -> 1 | B20: =IF('tips dataset'!$A20="Female",1,0) -> 0 | C20: =IF('tips dataset'!$B20="Yes",1,0) -> 0 | D20: =IF('tips dataset'!$B20="No",1,0) -> 1 | E20: =IF('tips dataset'!$C20="Sat",1,0) -> 1 | F20: =IF('tips dataset'!$C20="fri",1,0) -> 0 | G20: =IF('tips dataset'!$C20="Sun",1,0) -> 0 | H20: =IF('tips dataset'!$D20="Lunch",1,0) -> 0 | I20: =IF('tips dataset'!$D20="Dinner",1,0) -> 1 | J20: ='tips dataset'!$E20 -> 2 | K20: 16.97 | L20: 3.5 | M20: =L20/K20 -> 0.20624632 | N20: =K20/J20 -> 8.485 | O20: =L20/J20 -> 1.75 | P20: =IF('tips dataset'!$C20="thur",1,0) -> 0 | Q20: =IF(K20<15,"Low",IF(K20<25,"Medium",IF(K20<35,"High","Premium"))) -> Medium
A21: =IF('tips dataset'!$A21="Male",1,0) -> 0 | B21: =IF('tips dataset'!$A21="Female",1,0) -> 1 | C21: =IF('tips dataset'!$B21="Yes",1,0) -> 1 | D21: =IF('tips dataset'!$B21="No",1,0) -> 0 | E21: =IF('tips dataset'!$C21="Sat",1,0) -> 0 | F21: =IF('tips dataset'!$C21="fri",1,0) -> 1 | G21: =IF('tips dataset'!$C21="Sun",1,0) -> 0 | H21: =IF('tips dataset'!$D21="Lunch",1,0) -> 1 | I21: =IF('tips dataset'!$D21="Dinner",1,0) -> 0 | J21: ='tips dataset'!$E21 -> 2 | K21: 20.65 | L21: 3.35 | M21: =L21/K21 -> 0.1622276 | N21: =K21/J21 -> 10.325 | O21: =L21/J21 -> 1.675 | P21: =IF('tips dataset'!$C21="thur",1,0) -> 0 | Q21: =IF(K21<15,"Low",IF(K21<25,"Medium",IF(K21<35,"High","Premium"))) -> Medium
A22: =IF('tips dataset'!$A22="Male",1,0) -> 1 | B22: =IF('tips dataset'!$A22="Female",1,0) -> 0 | C22: =IF('tips dataset'!$B22="Yes",1,0) -> 0 | D22: =IF('tips dataset'!$B22="No",1,0) -> 1 | E22: =IF('tips dataset'!$C22="Sat",1,0) -> 0 | F22: =IF('tips dataset'!$C22="fri",1,0) -> 0 | G22: =IF('tips dataset'!$C22="Sun",1,0) -> 1 | H22: =IF('tips dataset'!$D22="Lunch",1,0) -> 0 | I22: =IF('tips dataset'!$D22="Dinner",1,0) -> 1 | J22: ='tips dataset'!$E22 -> 2 | K22: 17.92 | L22: 4.08 | M22: =L22/K22 -> 0.22767857 | N22: =K22/J22 -> 8.96 | O22: =L22/J22 -> 2.04 | P22: =IF('tips dataset'!$C22="thur",1,0) -> 0 | Q22: =IF(K22<15,"Low",IF(K22<25,"Medium",IF(K22<35,"High","Premium"))) -> Medium
A23: =IF('tips dataset'!$A23="Male",1,0) -> 0 | B23: =IF('tips dataset'!$A23="Female",1,0) -> 1 | C23: =IF('tips dataset'!$B23="Yes",1,0) -> 0 | D23: =IF('tips dataset'!$B23="No",1,0) -> 1 | E23: =IF('tips dataset'!$C23="Sat",1,0) -> 0 | F23: =IF('tips dataset'!$C23="fri",1,0) -> 0 | G23: =IF('tips dataset'!$C23="Sun",1,0) -> 1 | H23: =IF('tips dataset'!$D23="Lunch",1,0) -> 0 | I23: =IF('tips dataset'!$D23="Dinner",1,0) -> 1 | J23: ='tips dataset'!$E23 -> 2 | K23: 20.29 | L23: 2.75 | M23: =L23/K23 -> 0.13553475 | N23: =K23/J23 -> 10.145 | O23: =L23/J23 -> 1.375 | P23: =IF('tips dataset'!$C23="thur",1,0) -> 0 | Q23: =IF(K23<15,"Low",IF(K23<25,"Medium",IF(K23<35,"High","Premium"))) -> Medium
A24: =IF('tips dataset'!$A24="Male",1,0) -> 0 | B24: =IF('tips dataset'!$A24="Female",1,0) -> 1 | C24: =IF('tips dataset'!$B24="Yes",1,0) -> 0 | D24: =IF('tips dataset'!$B24="No",1,0) -> 1 | E24: =IF('tips dataset'!$C24="Sat",1,0) -> 0 | F24: =IF('tips dataset'!$C24="fri",1,0) -> 0 | G24: =IF('tips dataset'!$C24="Sun",1,0) -> 1 | H24: =IF('tips dataset'!$D24="Lunch",1,0) -> 0 | I24: =IF('tips dataset'!$D24="Dinner",1,0) -> 1 | J24: ='tips dataset'!$E24 -> 3 | K24: 15.77 | L24: 2.23 | M24: =L24/K24 -> 0.14140774 | N24: =K24/J24 -> 5.2566667 | O24: =L24/J24 -> 0.74333333 | P24: =IF('tips dataset'!$C24="thur",1,0) -> 0 | Q24: =IF(K24<15,"Low",IF(K24<25,"Medium",IF(K24<35,"High","Premium"))) -> Medium
... A244: =IF('tips dataset'!$A244="Male",1,0) -> 1 | B244: =IF('tips dataset'!$A244="Female",1,0) -> 0 | C244: =IF('tips dataset'!$B244="Yes",1,0) -> 1 | D244: =IF('tips dataset'!$B244="No",1,0) -> 0 | E244: =IF('tips dataset'!$C244="Sat",1,0) -> 1 | F244: =IF('tips dataset'!$C244="fri",1,0) -> 0 | G244: =IF('tips dataset'!$C244="Sun",1,0) -> 0 | H244: =IF('tips dataset'!$D244="Lunch",1,0) -> 0 | I244: =IF('tips dataset'!$D244="Dinner",1,0) -> 1 | J244: ='tips dataset'!$E244 -> 3 | K244: 18.78 | L244: 3 | M244: =L244/K244 -> 0.15974441 | N244: =K244/J244 -> 6.26 | O244: =L244/J244 -> 1 | P244: =IF('tips dataset'!$C244="thur",1,0) -> 0 | Q244: =IF(K244<15,"Low",IF(K244<25,"Medium",IF(K244<35,"High","Premium"))) -> Medium

Sheet Residual and RMSE
A1: RMSE(Root Mean Square Error)
A3: Rmse tells us,
A4: on average how far are the predicted values are from actual
B6: RMSE=(∑(Actual−Predicted)2​/n)^1/2​
A9: Relationship with Your Regression Output
A11: In Excel Regression Statistics:
A13: You had:
A15: Standard Error=1.022Standard\ Error = 1.022Standard Error=1.022
A17: For regression:
A19: RMSE≈StandardErrorRMSE \approx Standard ErrorRMSE≈StandardError
A21: Therefore:
A23: RMSE≈1.02RMSE \approx 1.02RMSE≈1.02
A25: Residual
A26: Residual = actual - predicted
A28: Axtual tip :
B29: 4.5
A30: predicted tip:
B31: 3.8
A32: residual =
B33: 4.5-3.8=0.70
A35: Positive residual means:
A37: Customer tipped more than expected.
A40: Example:
A42: Actual:
B43: 2.002.002.00
A45: Predicted:
B46: 3.503.503.50
A48: Residual:
B49: −1.50-1.50−1.50
A51: Negative residual means:
A53: Customer tipped less than expected.
A55: Residual Distsribuiton
A56: Residual distribution tells us:
A58: How the prediction errors are spread.
A60: Good regression models have residuals that:
A62: ✅ Center around zero
A64: ✅ Have both positive and negative values
A66: ✅ Look roughly bell-shaped

Sheet Data on tip by Sex 
A1: tip by female | B1: tip by male
A2: 1.01 | B2: 1.66
A3: 3.61 | B3: 3.5
A4: 5 | B4: 3.31
A5: 3.02 | B5: 4.71
A6: 1.67 | B6: 2
A7: 3.5 | B7: 3.12
A8: 2.75 | B8: 1.96
A9: 2.23 | B9: 3.23
A10: 3 | B10: 1.71
A11: 3 | B11: 1.57
A12: 2.45 | B12: 3
A13: 3.07 | B13: 3.92
... A87: 3 | B87: 1.48
B88: 2.18
B89: 1.5
B90: 2
B91: 6.7
B92: 5
B93: 1.73
B94: 2
B95: 2.5
B96: 2
B97: 2.74
B98: 2
B99: 2
... B158: 1.75

Sheet Data ontip by time
A1: Lunch tips | B1: Dinnertips
A2: 4 | B2: 1.01
A3: 3 | B3: 1.66
A4: 2.71 | B4: 3.5
A5: 3 | B5: 3.31
A6: 3.4 | B6: 3.61
A7: 1.83 | B7: 4.71
A8: 5 | B8: 2
A9: 2.03 | B9: 3.12
A10: 5.17 | B10: 1.96
A11: 2 | B11: 3.23
A12: 4 | B12: 1.71
A13: 5.85 | B13: 5
... A68: 2 | B68: 2.47
B69: 1
B70: 2.01
B71: 2.09
B72: 1.97
B73: 3
B74: 3.14
B75: 5
B76: 2.2
B77: 1.25
B78: 3.08
B79: 3
B80: 3.5
... B177: 3

Sheet Data Understanding
B3: number of records in the dataset | G3: =COUNT('tips dataset'!G1:G245) -> 243
B4: missing values | G4: 0
B5: duplicate observations | G5: 0
B6: percentage of customers are smokers | G6: =COUNTIF('tips dataset'!B1:$B$244,"Yes")/G3 -> 0.37860082
B7: percentage of customers visit during lunch and dinner | G7: Time | H7: Total Customers Visit
G8: Dinner | H8: 0.72427984
G9: Lunch | H9: 0.27572016
C11: Saturday has the highest customer volume | G11: DAY | H11: Total Customers Visit
G12: Sat | H12: 87
G13: Sun | H13: 76
G14: Thur | H14: 61
G15: Fri | H15: 19
B18: In this table we can see some intresting facts | G18: Day | H18: Total Customers Visit
A19: 1 | B19: on sat and sun all customers visit Only during zDinnner | G19: Sat | H19: 0.35802469
A20: 2 | B20: Meanwhile out of all customers visit restaurant | G20: Dinner | H20: 1
B21: on thur | G21: Sun | H21: 0.3127572
B22: 98.36% visted during lunch | G22: Dinner | H22: 1
A23: 3 | B23: On fri 63.16% visted during lunch and remaining 36.84% | G23: Thur | H23: 0.25102881
B24: during Dinner | G24: Dinner | H24: 0.016393443
G25: Lunch | H25: 0.98360656
G26: Fri | H26: 0.0781893
G27: Dinner | H27: 0.63157895
G28: Lunch | H28: 0.36842105

Sheet Working sheet Stat anal
B1: non smokre tip | C1: tip by smoker
B2: 1.01 | C2: 3
B3: 1.66 | C3: 1.76
B4: 3.5 | C4: 3.21
B5: 3.31 | C5: 2
B6: 3.61 | C6: 1.98
B7: 4.71 | C7: 3.76
B8: 2 | C8: 1
B9: 3.12 | C9: 2.09
B10: 1.96 | C10: 3.14
B11: 3.23 | C11: 5
B12: 1.71 | C12: 3.08
B13: 5 | C13: 3
... B93: 2.92 | C93: 2
B94: 2.31
B95: 1.68
B96: 2.5
B97: 2
B98: 2.52
B99: 4.2
B100: 1.48
B101: 2
B102: 2
B103: 2.18
B104: 1.5
B105: 2.83
... B152: 3

Sheet Basic EDA
B1: Customer Analysis
B3: 1.average bill amount | E3: =AVERAGE('tips dataset'!$F$2:$F$244) -> 19.813868
B5: 2.Average tip Amount | E5: =AVERAGE('tips dataset'!G2:G244) -> 3.0023868
B7: 3Average Tip percentage | E7: =SUM('tips dataset'!$G$2:$G$244)/SUM('tips dataset'!F2:F244) -> 0.15152956
B10: Gender Analysis
B12: 1. Do males spend more than females? | F12: Sex | G12: Sum of total_bill | H12: Sum of tip | I12: Grand Total
F13: Female | G13: 1557.95 | H13: 244.51 | I13: =SUM(G13:H13) -> 1802.46
F14: Male | G14: 3256.82 | H14: 485.07 | I14: =SUM(G14:H14) -> 3741.89
B16: 2. Do males leave larger tips?
B17: 3. Which gender has a higher tip percentage?
F18: Sex | G18: Sum of tip | H18: Sum of total_bill | I18: Tip %
F19: Female | G19: 244.51 | H19: 1557.95 | I19: =G19/H19 -> 0.15694342
F20: Male | G20: 485.07 | H20: 3256.82 | I20: =G20/H20 -> 0.14893976
B21: Tip Is independent of gender
B24: Smoking Analysis
B26: 1. Do smokers generate higher bills? | F26: smoker | G26: Total revenue | H26: Count of smoker | I26: Bill Per person
F27: No | G27: 2897.43 | H27: 151 | I27: =G27/H27 -> 19.188278
F28: Yes | G28: 1917.34 | H28: 92 | I28: =G28/H28 -> 20.840652
B30: 2. Do smokers leave larger tips? | F30: smoker | G30: Total tip | H30: % Tip | I30: Per person tip
F31: No | G31: 451.77 | H31: =G31/G27 -> 0.15592094 | I31: =G31/H27 -> 2.9918543
F32: Yes | G32: 277.81 | H32: =G32/G28 -> 0.14489345 | I32: =G32/H28 -> 3.0196739
B34: 3. Is the difference statistically significant? | G34: non smokers give preovide more revenue to restaurant But
G35: Bill per customer for smoker and non smoker is almost equal
G36: simillarly smoker and non smokers tip almost equally
B38: Smokers percentage | F38: Smoker | G38: Count of smoker | H38: percent of amoker
F39: No | G39: 151 | H39: 0.62139918
F40: Yes | G40: 92 | H40: 0.37860082
B42: Time Analysis
B44: 1. Does dinner generate more revenue than lunch? | H44: Time | I44: Sum of total_bill | J44: Sum of tip | K44: Average of size
C45: Dinner roduces more revenue $3660.3 while | H45: Dinner | I45: 3660.3 | J45: 546.07 | K45: 2.6306818
C46: lunch produces $1154.5 of revenue | H46: Lunch | I46: 1154.47 | J46: 183.51 | K46: 2.4179104
B48: 2. Does dinner produce higher tips?
C49: Yes Tips produce by Dinner 546.03$ and during lunch 183.5 $
B51: 3. What is the average customer group size during lunch vs dinner?
C52: almost simillar | E52: Lunch | F52: 2.42
E53: Dinner | F53: 2.63
B55: Day Analysis
B57: Which day generates the highest revenue? | F57: Day | G57: Sum of total_bill
F58: Sat | G58: 1778.4
B60: Which day generates the highest tips? | F60: Day | G60: Sum of tip
...

Sheet SA on tip by smoker vs nonsmoke
A1: Question
A3: Do smokers and non-smokers tip differently?
A5: H0
A7: No significant difference exists.
A9: H1
A11: A significant difference exists.
B12: non smokre tip | C12: tip by smoker
A13: Mean | B13: 2.9918543 | C13: 3.0196739
A14: Variance | B14: 1.8966525 | C14: 1.9743922
A15: Observations | B15: 151 | C15: 92
A16: Hypothesized Mean Difference | B16: 0
A17: df | B17: 189
A18: t Stat | B18: -0.15082556
A19: P(T<=t) one-tail | B19: 0.44013709
A20: t Critical one-tail | B20: 1.6529558
A21: P(T<=t) two-tail | B21: 0.88027418
A22: t Critical two-tail | B22: 1.9725951
A24: Hypothesis Test: Smoking Status vs Tip Amount
A26: A two-sample t-test assuming unequal variances was conducted to determine whether smoking status influences tipping behavior.
A28: Mean tip (Non-Smoker): 2.99
A29: Mean tip (Smoker): 3.02
A30: t-statistic: -0.151
A31: p-value (two-tailed): 0.880
A33: Since the p-value (0.880) is greater than the significance level of 0.05, the null hypothesis was not rejected.
A35: Conclusion: Smoking status does not appear to have a statistically significant impact on the amount of tip left by customers. The average tipping behavior of smokers and non-smokers is essentially the same.
A37: Business Recomnedations
A38: Since Smoking doesn’t affects the tip
A39: Waiters should focus on other things like food Quality,personal experience,food recommmendaions etc

Sheet SA on tips by gender
A1: Hypothesis Test 2
A3: Question
A5: Do males and females tip differently?
A7: H0
A9: No significant difference exists.
A11: H1
A13: A significant difference exists.
A15: t-Test: Two-Sample Assuming Unequal Variances
B17: tip by female | C17: tip by male
A18: Mean | B18: 2.8431395 | C18: 3.0896178
A19: Variance | B19: 1.3519771 | C19: 2.2174242
A20: Observations | B20: 86 | C20: 157
A21: Hypothesized Mean Difference | B21: 0
A22: df | B22: 213
A23: t Stat | B23: -1.4267483
A24: P(T<=t) one-tail | B24: 0.077558312
A25: t Critical one-tail | B25: 1.6520389
A26: P(T<=t) two-tail | B26: 0.15511662
A27: t Critical two-tail | B27: 1.9711639
A29: Hypothesis Test: Sex vs Tip Amount
A31: A two-sample t-test assuming unequal variances was conducted to determine whether customer Sex influences tipping behavior.
A33: Mean tip (Female): 2.84
A34: Mean tip (male): 3.09
A35: t-statistic: -1.427
A36: p-value (two-tailed): 0.155
A38: Since the p-value (0.155) is greater than the significance level of 0.05, the null hypothesis was not rejected.
A40: Conclusion: Sex of customer does not appear to have a statistically significant impact on the amount of tip left by customers.
A41: The analysis did not find sufficient evidence to conclude that males and females differ in their average tipping behavior.
A43: Business Insight
A44: Customer sex alone is not a reliable predictor of tipping behavior..
A45: Restaurant managers should focus on other factors such as total bill amount, party size, dining time, and day of visit,
A46: which may have a greater influence on tip amounts

Sheet Time Hypo testing
A1: Hypothesis Test 3
A3: Question
A5: Does dinner produce higher tips than lunch?
A7: H0
A9: No significant difference exists.
A11: H1
A13: A significant difference exists.
A15: t-Test: Two-Sample Assuming Unequal Variances
B17: Lunch tips | C17: Dinnertips
A18: Mean | B18: 2.7389552 | C18: 3.1026705
A19: Variance | B19: 1.4667186 | C19: 2.0627934
A20: Observations | B20: 67 | C20: 176
A21: Hypothesized Mean Difference | B21: 0
A22: df | B22: 140
A23: t Stat | B23: -1.9838827
A24: P(T<=t) one-tail | B24: 0.024612296
A25: t Critical one-tail | B25: 1.6558105
A26: P(T<=t) two-tail | B26: 0.049224593
A27: t Critical two-tail | B27: 1.9770537
A29: Hypothesis Test: Time vs Tip Amount
A31: A two-sample t-test assuming unequal variances was conducted to determine whether time influences tipping behavior.
A33: Mean tip (Lunch): 2.74
A34: Mean tip (Dinner): 3.10
A35: t-statistic: -1.984
A36: p-value (two-tailed): 0.049
A38: The null hypothesis stated that there is no significant difference in average tip amounts between lunch and dinner customers.
A40: Since the p-value 0.049 is less than the significant level of 0.05,the null hypothesis was rejected
A43: Conclusion:
A44: The analysis provide sufficient evidence to conclude that dinner and lunch time may influence tipping behaviour.
A45: Customers dining during dinner leave significantly higher tips on average than customers dining during lunch
A47: Business recommnedarion
A48: Assign senior waitsatff during dinner time

Sheet Correlation Analysis
A1: Correlation Matrix
B4: Male | C4: Female | D4: Smoker Yes | E4: smoker No | F4: Sat | G4: fri | H4: Sun | I4: Lunch | J4: Dinner | K4: size | L4: total_bill | M4: tip | N4: tip % | O4: Per person Bill | P4: Per person tip | Q4: thur
A5: Male | B5: 1
A6: Female | B6: -1 | C6: 1
A7: Smoker Yes | B7: 0.009930188 | C7: -0.009930188 | D7: 1
A8: smoker No | B8: -0.009930188 | C8: 0.009930188 | D8: -1 | E8: 1
A9: Sat | B9: 0.05008512 | C9: -0.05008512 | D9: 0.16036626 | E9: -0.16036626 | F9: 1
A10: fri | B10: -0.072949996 | C10: 0.072949996 | D10: 0.24670851 | E10: -0.24670851 | F10: -0.21749542 | G10: 1
A11: Sun | B11: 0.16515495 | C11: -0.16515495 | D11: -0.17886122 | E11: 0.17886122 | F11: -0.50378576 | G11: -0.19647231 | H11: 1
A12: Lunch | B12: -0.19812862 | C12: 0.19812862 | D12: -0.063911231 | E12: 0.063911231 | F12: -0.46076385 | G12: 0.060415618 | H12: -0.41622641 | I12: 1
A13: Dinner | B13: 0.19812862 | C13: -0.19812862 | D13: 0.063911231 | E13: -0.063911231 | F13: 0.46076385 | G13: -0.060415618 | H13: 0.41622641 | I13: -1 | J13: 1
A14: size | B14: 0.083248017 | C14: -0.083248017 | D14: -0.13056441 | E14: 0.13056441 | F14: -0.043040411 | G14: -0.143033 | H14: 0.19171284 | I14: -0.1000453 | J14: 0.1000453 | K14: 1
A15: total_bill | B15: 0.033500432 | C15: -0.033500432 | D15: -0.059918798 | E15: 0.059918798 | F15: 0.0034883113 | G15: -0.092010874 | H15: 0.053373665 | I15: -0.030551354 | J15: 0.030551354 | K15: 0.10717881 | L15: 1
A16: tip | B16: 0.0065706532 | C16: -0.0065706532 | D16: -0.035600806 | E16: 0.035600806 | F16: -0.038987062 | G16: -0.034217529 | H16: 0.039551419 | I16: 0.023386682 | J16: -0.023386682 | K16: -0.028984087 | L16: 0.67499786 | M16: 1
A17: tip % | B17: -0.013580449 | C17: 0.013580449 | D17: -0.0049712875 | E17: 0.0049712875 | F17: -0.069394963 | G17: 0.069625817 | H17: -0.011802901 | I17: 0.075337505 | J17: -0.075337505 | K17: -0.14945915 | L17: -0.33939963 | M17: 0.34240766 | N17: 1
A18: Per person Bill | B18: -0.046870891 | C18: 0.046870891 | D18: 0.016577613 | E18: -0.016577613 | F18: 0.02834457 | G18: 0.00061562991 | H18: -0.10561031 | I18: 0.075517917 | J18: -0.075517917 | K18: -0.44569109 | L18: 0.78321976 | M18: 0.59160562 | N18: -0.22352996 | O18: 1
A19: Per person tip | B19: -0.054567026 | C19: 0.054567026 | D19: 0.019503373 | E19: -0.019503373 | F19: -0.02131911 | G19: 0.038667115 | H19: -0.096953203 | I19: 0.12029309 | J19: -0.12029309 | K19: -0.48976279 | L19: 0.50503494 | M19: 0.82242637 | N19: 0.33661999 | O19: 0.77441626 | P19: 1
A20: thur | B20: -0.18679554 | C20: 0.18679554 | D20: -0.13882071 | E20: 0.13882071 | F20: -0.43234113 | G20: -0.16860949 | H20: -0.39055103 | I20: 0.917076 | J20: -0.917076 | K20: -0.068834154 | L20: -0.0039556262 | M20: 0.022003491 | N20: 0.046237752 | O20: 0.081199361 | P20: 0.10329436 | Q20: 1
A23: Key Insights
A25: 1. Total Bill,Per person bill and Per person tip are the strongest predictors of Tip
A26: Correlation between tip and total Bill = 0.675
A27: tip and Bill per person | B27: 0.59161
A28: Tip and tip per person | B28: 0.82243
A29: customers who spends more,have higher Bill per person usually tips more
A31: 2.Party size influences spending
A32: Dinner has moderate relation with sat and sun 0.460 and 0.4162 respectively
A43: larger parties generate Higher bills
A45: 3.Party size has a weaker direct impact on tip
A47: correlation = 0.488
A48: Although larger groups leave higher tips,much of this is likely because larger groups
A49: produce larger bills

Sheet ph-6 Regression 
A1: Phase 6: Predictive Modeling
A3: Build:
A5: Model 1
A7: Tip = f(Total Bill)
A9: Model 2
A11: Tip = f(Total Bill + Size)
A13: Model 3
A15: Tip = f(Total Bill + Size + Gender + Day + Time + Smoker)
A17: Questions
A19: 1. Which model performs best?
A20: 2. Which variables are statistically significant?
A21: 3. What is the final prediction equation?

Sheet Model 1
A1: Model 1 | K1: RESIDUAL OUTPUT
A3: Tip = f(Total Bill) | K3: Observation | L3: Predicted tip | M3: Residuals
K4: 1 | L4: 2.6307658 | M4: -1.6207658
A5: SUMMARY OUTPUT | K5: 2 | L5: 2.2070734 | M5: -0.54707341
K6: 3 | L6: 3.1955144 | M6: 0.30448559
A7: Regression Statistics | K7: 4 | L7: 3.2505099 | M7: 0.059490059
A8: Multiple R | B8: 0.67499786 | K8: 5 | L8: 3.7195026 | M8: -0.1095026
A9: R Square | B9: 0.45562211 | K9: 6 | L9: 3.7843488 | M9: 0.92565122
A10: Adjusted R Square | B10: 0.45336328 | K10: 7 | L10: 1.8692864 | M10: 0.13071362
A11: Standard Error | B11: 1.0239997 | K11: 8 | L11: 3.9316422 | M11: -0.81164224
A12: Observations | B12: 243 | K12: 9 | L12: 2.4501228 | M12: -0.49012285
K13: 10 | L13: 2.4260371 | M13: 0.80396288
A14: ANOVA | K14: 11 | L14: 2.0082425 | M14: -0.29824247
B15: df | C15: SS | D15: MS | E15: F | F15: Significance F | K15: 12 | L15: 4.7079436 | M15: 0.29205639
A16: Regression | B16: 1 | C16: 211.50517 | D16: 211.50517 | E16: 201.70718 | F16: 1.135211e-33 | K16: 13 | L16: 2.4853251 | M16: -0.91532506
A17: Residual | B17: 241 | C17: 252.70665 | D17: 1.0485753 | K17: 14 | L17: 3.1488562 | M17: -0.14885625
A18: Total | B18: 242 | C18: 464.21182 | K18: 15 | L18: 2.430669 | M18: 0.58933101
K19: 16 | L19: 3.0559714 | M19: 0.86402859
B20: Coefficients | C20: Standard Error | D20: t Stat | E20: P-value | F20: Lower 95% | G20: Upper 95% | H20: Lower 95.0% | I20: Upper 95.0% | K20: 17 | L20: 2.206147 | M20: -0.53614703
A21: Intercept | B21: 0.92345177 | C21: 0.16044339 | D21: 5.7556236 | E21: 2.612348e-08 | F21: 0.60740136 | G21: 1.2395022 | H21: 0.60740136 | I21: 1.2395022 | K21: 18 | L21: 2.7582659 | M21: 0.95173409
A22: total_bill | B22: 0.10492323 | C22: 0.0073877293 | D22: 14.202365 | E22: 1.135211e-33 | F22: 0.090370465 | G22: 0.11947599 | H22: 0.090370465 | I22: 0.11947599 | K22: 19 | L22: 2.8212593 | M22: 0.67874066
K23: 20 | L23: 3.1621649 | M23: 0.18783505
A24: R Square | B24: 0.4556 | K24: 21 | L24: 2.7169185 | M24: 1.3630815
A25: 45.56% of predicted tips depend upon total | K25: 22 | L25: 2.9364692 | M25: -0.18646917
A26: R^2 adjusted | B26: 0.4536 | K26: 23 | L26: 2.5177481 | M26: -0.28774815
K27: 24 | L27: 5.0933152 | M27: 2.4866848
A28: Check for Overfitting | K28: 25 | L28: 2.8929296 | M28: 0.2870704
A29: R^2-R^2 adjusted | B29: =B24-B26 -> 0.002 | K29: 26 | L29: 3.0914211 | M29: -0.75142106
A30: Therefor there is a very little evidence of overfitting | K30: 27 | L30: 2.2954184 | M30: -0.2954184
A31: this model explains 45.6% of tips behaviour | K31: 28 | L31: 2.232425 | M31: -0.23242497
A32: Even after considering the nu,ber of predcitors,model still explains 45.365% if tips behaiour | K32: 29 | L32: 3.0670879 | M32: 1.2329121
K33: 30 | L33: 2.8771812 | M33: 0.12281876
A34: MSME | B34: =SQRT(C17/B12) -> 1.019777 | K34: 31 | L34: 1.9415435 | M34: -0.49154355
A35: Standard error | B35: 1.02 | K35: 32 | L35: 3.1414453 | M35: -0.64144526
A36: Since MSME is 1.02 and Standard error is also 1.02,we can conclude that | K36: 33 | L36: 2.4519756 | M36: 0.54802441
A37: predcited tips are of by about 1$ per ubit average customer | K37: 34 | L37: 3.3582168 | M37: -0.90821676
A38: F | B38: =E16 -> 201.70718 | K38: 35 | L38: 2.7039493 | M38: 0.56605069
A39: greater the F better the model | K39: 36 | L39: 3.4780585 | M39: 0.12194153
A40: t stat | B40: 5.756 | C40: >2 | K40: 37 | L40: 2.7601187 | M40: -0.76011865
A41: Significance F | B41: 1.352*10^-33 | C41: <0.05 | K41: 38 | L41: 2.8175538 | M41: 0.25244616
...

Sheet Model 2
A1: Model 2 | J1: RESIDUAL OUTPUT
A3: Tip = f(Total Bill + Size) | J3: Observation | K3: Predicted tip | L3: Residuals
J4: 1 | K4: 2.6307658 | L4: -1.6207658
A5: SUMMARY OUTPUT | J5: 2 | K5: 2.2070734 | L5: -0.54707341
J6: 3 | K6: 3.1955144 | L6: 0.30448559
A7: Regression Statistics | J7: 4 | K7: 3.2505099 | L7: 0.059490059
A8: Multiple R | B8: 0.68327752 | J8: 5 | K8: 3.7195026 | L8: -0.1095026
A9: R Square | B9: 0.46686817 | J9: 6 | K9: 3.7843488 | L9: 0.92565122
A10: Adjusted R Square | B10: 0.46242541 | J10: 7 | K10: 1.8692864 | L10: 0.13071362
A11: Standard Error | B11: 1.0154763 | J11: 8 | K11: 3.9316422 | L11: -0.81164224
A12: Observations | B12: 243 | J12: 9 | K12: 2.4501228 | L12: -0.49012285
J13: 10 | K13: 2.4260371 | L13: 0.80396288
A14: ANOVA | J14: 11 | K14: 2.0082425 | L14: -0.29824247
B15: df | C15: SS | D15: MS | E15: F | F15: Significance F | J15: 12 | K15: 4.7079436 | L15: 0.29205639
A16: Regression | B16: 2 | C16: 216.72572 | D16: 108.36286 | E16: 105.08504 | F16: 1.6601721e-33 | J16: 13 | K16: 2.4853251 | L16: -0.91532506
A17: Residual | B17: 240 | C17: 247.48609 | D17: 1.0311921 | J17: 14 | K17: 3.1488562 | L17: -0.14885625
A18: Total | B18: 242 | C18: 464.21182 | J18: 15 | K18: 2.430669 | L18: 0.58933101
J19: 16 | K19: 3.0559714 | L19: 0.86402859
B20: Coefficients | C20: Standard Error | D20: t Stat | E20: P-value | F20: Lower 95% | G20: Upper 95% | H20: Lower 95.0% | I20: Upper 95.0% | J20: 17 | K20: 2.206147 | L20: -0.53614703
A21: Intercept | B21: 0.67216379 | C21: 0.19439185 | D21: 3.4577776 | E21: 0.00064418198 | F21: 0.28923174 | G21: 1.0550958 | H21: 0.28923174 | I21: 1.0550958 | J21: 18 | K21: 2.7582659 | L21: 0.95173409
A22: size | B22: 0.19234632 | C22: 0.085486043 | D22: 2.2500318 | E22: 0.025353509 | F22: 0.023947562 | G22: 0.36074507 | H22: 0.023947562 | I22: 0.36074507 | J22: 19 | K22: 2.8212593 | L22: 0.67874066
A23: total_bill | B23: 0.092637395 | C23: 0.0091372069 | D23: 10.138481 | E23: 2.4602759e-20 | F23: 0.074638033 | G23: 0.11063676 | H23: 0.074638033 | I23: 0.11063676 | J23: 20 | K23: 3.1621649 | L23: 0.18783505
J24: 21 | K24: 2.7169185 | L24: 1.3630815
A25: R^2 | B25: 0.4669 | J25: 22 | K25: 2.9364692 | L25: -0.18646917
A26: R^2 adjusted | B26: 0.4624 | J26: 23 | K26: 2.5177481 | L26: -0.28774815
A27: Model explains 46.7% of tips variations. | J27: 24 | K27: 5.0933152 | L27: 2.4866848
A28: even after adjusting for the number of factors the model still explains 46.24% of tips variations | J28: 25 | K28: 2.8929296 | L28: 0.2870704
A29: Check for overfitting | J29: 26 | K29: 3.0914211 | L29: -0.75142106
A30: R^2-R^2 Adjusted | B30: =B25-B26 -> 0.0045 | J30: 27 | K30: 2.2954184 | L30: -0.2954184
A31: Since R^2 is very close to adjusted R^2,there is little evdence of overfitting | J31: 28 | K31: 2.232425 | L31: -0.23242497
A32: Standard error | B32: 1.01 | J32: 29 | K32: 3.0670879 | L32: 1.2329121
A33: RMSE | B33: =SQRT(C17/B12) -> 1.0091884 | J33: 30 | K33: 2.8771812 | L33: 0.12281876
A34: RMSE is 1.009 and standard error is 1.01, | J34: 31 | K34: 1.9415435 | L34: -0.49154355
A35: therefore we can coclude that predicted tips are off by about 1$ per unit average | J35: 32 | K35: 3.1414453 | L35: -0.64144526
A36: intercept | B36: 0.672 | J36: 33 | K36: 2.4519756 | L36: 0.54802441
A37: F = 105.085 | J37: 34 | K37: 3.3582168 | L37: -0.90821676
A38: F value is large | J38: 35 | K38: 2.7039493 | L38: 0.56605069
A39: Significance F | B39: 1.7*10^-33<0..05 | J39: 36 | K39: 3.4780585 | L39: 0.12194153
A40: Null hypothesis is rejected | J40: 37 | K40: 2.7601187 | L40: -0.76011865
A41: t stat(total bill) | B41: 10.14 | C41: >2 | J41: 38 | K41: 2.8175538 | L41: 0.25244616
...

Sheet Model 3
A1: Model 3 | M1: RESIDUAL OUTPUT
F2: H0 | G2: No significant difference exists.
A3: Tip = f(Total Bill + Size + Gender + Day + Time + Smoker) | F3: H1 | G3: A significant difference exists. | M3: Observation | N3: Predicted tip | O3: Residuals
M4: 1 | N4: 2.7364916 | O4: -1.7264916
A5: Questions | M5: 2 | N5: 2.2503963 | O5: -0.59039633
M6: 3 | N6: 3.2578574 | O6: 0.2421426
A7: 1. Which model performs best? | M7: 4 | N7: 3.3338687 | O7: -0.023868707
A8: 2. Which variables are statistically significant? | M8: 5 | N8: 3.8062634 | O8: -0.19626341
A9: 3. What is the final prediction equation? | M9: 6 | N9: 3.8380649 | O9: 0.87193513
M10: 7 | N10: 1.926067 | O10: 0.073933025
A11: SUMMARY OUTPUT | M11: 8 | N11: 3.9881926 | O11: -0.86819262
M12: 9 | N12: 2.5180802 | O12: -0.55808018
A13: Regression Statistics | M13: 10 | N13: 2.493531 | O13: 0.73646901
A14: Multiple R | B14: 0.68485627 | M14: 11 | N14: 2.0676969 | O14: -0.35769693
A15: R Square | B15: 0.46902811 | M15: 12 | N15: 4.8137245 | O15: 0.18627553
A16: Adjusted R Square | B16: 0.45087523 | M16: 13 | N16: 2.5539598 | O16: -0.98395977
A17: Standard Error | B17: 1.0263274 | M17: 14 | N17: 3.1903439 | O17: -0.19034388
A18: Observations | B18: 243 | M18: 15 | N18: 2.5325445 | O18: 0.48745549
M19: 16 | N19: 3.1355868 | O19: 0.78441323
A20: ANOVA | M20: 17 | N20: 2.2837447 | O20: -0.61374465
B21: df | C21: SS | D21: MS | E21: F | F21: Significance F | M21: 18 | N21: 2.8121951 | O21: 0.89780486
A22: Regression | B22: 8 | C22: 217.72839 | D22: 27.216049 | E22: 25.837662 | F22: 2.032267e-28 | M22: 19 | N22: 2.9106932 | O22: 0.58930676
A23: Residual | B23: 234 | C23: 246.48342 | D23: 1.053348 | M23: 20 | N23: 3.1269625 | O23: 0.22303755
A24: Total | B24: 242 | C24: 464.21182 | M24: 21 | N24: 2.6931059 | O24: 1.3868941
M25: 22 | N25: 2.9511738 | O25: -0.20117378
B26: Coefficients | C26: Standard Error | D26: t Stat | E26: P-value | F26: Lower 95% | G26: Upper 95% | H26: Lower 95.0% | I26: Upper 95.0% | M26: 23 | N26: 2.5243955 | O26: -0.29439552
A27: Intercept | B27: 0.71405129 | C27: 0.23384505 | D27: 3.0535233 | E27: 0.002523355 | F27: 0.25334062 | G27: 1.174762 | H27: 0.25334062 | I27: 1.174762 | M27: 24 | N27: 5.0753153 | O27: 2.5046847
A28: sex | B28: -0.03429252 | C28: 0.14219877 | D28: -0.24115905 | E28: 0.80964303 | F28: -0.31444595 | G28: 0.24586091 | H28: -0.31444595 | I28: 0.24586091 | M28: 25 | N28: 2.8725039 | O28: 0.30749613
A29: smoker | B29: -0.083248126 | C29: 0.1477206 | D29: -0.56355123 | E29: 0.57359923 | F29: -0.37428041 | G29: 0.20778415 | H29: -0.37428041 | I29: 0.20778415 | M29: 26 | N29: 3.0348997 | O29: -0.69489975
A30: Sat | B30: 0.037029723 | C30: 0.47193763 | D30: 0.078463173 | E30: 0.93752668 | F30: -0.89275991 | G30: 0.96681936 | H30: -0.89275991 | I30: 0.96681936 | M30: 27 | N30: 2.2634951 | O30: -0.26349508
A31: fri | B31: 0.15715336 | C31: 0.39502288 | D31: 0.39783357 | E31: 0.69111557 | F31: -0.62110241 | G31: 0.93540913 | H31: -0.62110241 | I31: 0.93540913 | M31: 28 | N31: 2.1992895 | O31: -0.1992895
A32: Sun | B32: 0.13393348 | C32: 0.47287251 | D32: 0.2832338 | E32: 0.77724803 | F32: -0.79769803 | G32: 1.065565 | H32: -0.79769803 | I32: 1.065565 | M32: 29 | N32: 3.0500134 | O32: 1.2499866
A33: time | B33: -0.067868408 | C33: 0.44552903 | D33: -0.15233218 | E33: 0.87905621 | F33: -0.94562905 | G33: 0.80989223 | H33: -0.94562905 | I33: 0.80989223 | M33: 30 | N33: 2.890745 | O33: 0.109255
A34: size | B34: 0.17609 | C34: 0.089712357 | D34: 1.9628289 | E34: 0.050850843 | F34: -0.00065712249 | G34: 0.35283713 | H34: -0.00065712249 | I34: 0.35283713 | M34: 31 | N34: 1.9028108 | O34: -0.4528108
A35: total_bill | B35: 0.094419969 | C35: 0.0096267971 | D35: 9.8080356 | E35: 3.0340227e-19 | F35: 0.075453699 | G35: 0.11338624 | H35: 0.075453699 | I35: 0.11338624 | M35: 32 | N35: 3.0858865 | O35: -0.58588653
M36: 33 | N36: 2.4573573 | O36: 0.54264266
A37: RMSE | B37: =SQRT(C23/B18) -> 1.007142 | M37: 34 | N37: 3.3411218 | O37: -0.89112178
A38: R Square | B38: 0.46902811 | M38: 35 | N38: 2.6798871 | O38: 0.59011286
A39: The model explains 46.90% of tips variations in tips | M39: 36 | N39: 3.4489345 | O39: 0.15106545
A40: After adjustingfor the number of the predictiors ,45.1% of the variation remains explained by the model. | M40: 37 | N40: 2.7171798 | O40: -0.71717979
...

Sheet Model comparison
B3: Model 1 | D3: Model2 | F3: Model3
B4: Regression Statistics | D4: Regression Statistics | F4: Regression Statistics
B5: Multiple R | C5: 0.67499786 | D5: Multiple R | E5: 0.68327752 | F5: Multiple R | G5: 0.68485627
B6: R Square | C6: 0.45562211 | D6: R Square | E6: 0.46686817 | F6: R Square | G6: 0.46902811
B7: Adjusted R Square | C7: 0.45336328 | D7: Adjusted R Square | E7: 0.46242541 | F7: Adjusted R Square | G7: 0.45087523
B8: Standard Error | C8: 1.0239997 | D8: Standard Error | E8: 1.0154763 | F8: Standard Error | G8: 1.0263274
B9: Observations | C9: 243 | D9: Observations | E9: 243 | F9: Observations | G9: 243
B10: RSME | C10: =SQRT('Model 1'!C17/'Model 1'!B12) -> 1.019777 | D10: RMSE | E10: ='Model 2'!$B$33 -> 1.0091884 | G10: ='Model 3'!B37 -> 1.007142
B12: RMSE and standard error for model 1,model2 and model3 are almost same
B13: in model 2 adjusted R^2 is 0.4667 largest among 3
B14: Model 2 is best
B15: Conclusion'
B16: Size and total bill explains customer behaviour in best way

Sheet Regression explain
A1: SECTION 1: Regression Statistics | H1: SECTION 3: Coefficients Table
A3: Your output: | H3: This is where managers and analysts spend most of their time.
A5: Metric | B5: Value | H5: Intercept = 0.9489
A6: Multiple R | B6: 0.6846 | H6: if all variables were 0
A7: R Square | B7: 0.4687
A8: Adjusted R Square | B8: 0.4552 | H8: predicted tip = 0.9489
A9: Standard Error | B9: 1.022 | H9: Total bill
A10: Observations | B10: 243 | H10: coef 0.0942
H11: p value 1.85*10^-19 < 0.05
A12: Multiple R | B12: 0.6846 | H12: t stat | I12: 9.87
A13: Measures correlation between Actual tip and predicted tips | H13: Null hypothesis rejected
A14: closer to 1 Better fit | H14: total bill affects tip signifcant
A15: 0.6846 Moderately strong relationship | I15: 0.174
H16: Size | I16: 0.0515 | J16: >0.05
A17: 2.R Square | H17: coeff
A18: R^2 | B18: 0.4687 | H18: pvalue
A19: it means 48.67% of variation in tip is explained by your predictors | H19: null hypothesis is not rejected
A20: your model eplain about 47% of that beahviour | H20: almost significant
A21: the remaining
A22: 100-47 = 53% by another factors not included in model | H22: Sex | I22: -0.03707
H23: Coeff | I23: 0.793 | J23: >0.05
A24: 3.Adjusted Rsquare | H24: p value | I24: -0.26 | J24: <0
A25: adjusted R^2 0.4552 | H25: t stat
A26: let say we added random variables | H26: Sex is not significant'
A27: Hair color
A28: Birth month | H28: Time | I28: -0.041
A29: Favorite movies | H29: Coeff | I29: 0.8 | J29: >0.05
A30: R^2 almost always increases | H30: p value | I30: -0.24 | J30: <0
A31: Adusted R^2 always increases | H31: t stat
A32: Adjusted R^2 penalises useless variables | H32: Time is not significant
A33: use it for model comparison
H34: Day | I34: -0.035
A35: 4.Standard error | B35: 1.022 | H35: coeff | I35: 0.52 | J35: >0.05
A36: prediction error | H36: pvalue | I36: -0.64 | J36: <0
A37: Meaning on avg,predicted tips are off by about: ±1.02 dollars. Smaller is better. | H37: t stat
H38: day is not significant
A39: Section 02 Anova table
A40: Source | B40: df | C40: SS | D40: MS | E40: F | F40: Sig F | H40: Confidence Interval
A41: Regression | B41: 6 | C41: 217.56 | D41: 36.26 | E41: 34.69 | F41: 6.27e-30
A42: Residual | B42: 236 | C42: 246.65 | D42: 1.045 | H42: Example:
...

Sheet Working Sheet
A1: Row Labels | B1: Sum of total_bill | D1: Row Labels | E1: Sum of tip | K1: Row Labels | L1: Sum of total_bill | N1: Row Labels | O1: Sum of total_bill
A2: Sun | B2: 1627.16 | D2: Female | E2: 244.51 | G2: Row Labels | H2: Sum of tip | K2: Dinner | L2: 3660.3 | N2: Dinner | O2: 3660.3
A3: Fri | B3: 325.88 | D3: Male | E3: 485.07 | G3: No | H3: 451.77 | K3: Lunch | L3: 1154.47 | N3: Lunch | O3: 1154.47
A4: Sat | B4: 1778.4 | D4: Grand Total | E4: 729.58 | G4: Yes | H4: 277.81 | K4: Grand Total | L4: 4814.77 | N4: Grand Total | O4: 4814.77
A5: Thur | B5: 1083.33 | G5: Grand Total | H5: 729.58
A6: Grand Total | B6: 4814.77

Sheet DashBoard
A1: Restarunt tips and customer Behaviuor Analysis DashBoard
A3: KPI cards
C4: Sum of total_bill | E4: Sum of tip | G4: Average of total_bill | J4: Average % tip
B5: Total revenue | C5: 4814.77 | D5: Total tips | E5: 729.58 | F5: Average bill | G5: 19.813868 | I5: AverageTIp% | J5: =E5/C5 -> 0.15152956
A6: Total Revenue smoker customer | F6: Total Revenue smoker customer
A7: Smoker | B7: Sum of total_bill | F7: Smoker | G7: Sum of total_bill
A8: Yes | B8: 1917.34 | F8: No | G8: 2897.43
A9: Average Revenue smoker customer | F9: Total Revenue non smoker customer
A10: Smoker | B10: Average of total_bill | F10: Smoker | G10: Average of total_bill
A11: Yes | B11: 20.840652 | F11: No | G11: 19.188278
A12: Average tip per smoker customer | F12: Average tip per non smoker cusomer
A13: Smoker | B13: Average of tip | F13: Smoker | G13: Average of tip
A14: Yes | B14: 3.0196739 | F14: No | G14: 2.9918543
A20: highest revenue day | F20: customer segment
A21: Day | B21: revenue | C21: Segment | D21: Range | E21: Count of cutomers | F21: Customer Segment % | G21: Avg Bill | H21: Avg Tip | I21: Avg Tip% | J21: total revenue | K21: % revenue contribution | L21: Tips | M21: % tips contribution
A22: Fri | B22: 325.88 | C22: Medium | D22: 15$-25$ | E22: =COUNTIFS('tips dataset'!$F$1:$F$244,">15",'tips dataset'!$F$1:$F$244,"<25") -> 108 | F22: =DashBoard!$E22/SUM(DashBoard!$E$22:$E$25) -> 0.44628099 | G22: =AVERAGEIFS('tips dataset'!$F$1:$F$244,'tips dataset'!$F$1:$F$244,">15",'tips dataset'!F1:F244,"<25") -> 19.070093 | H22: =AVERAGEIFS('tips dataset'!$G$1:$G$244,'tips dataset'!$F$1:$F$244,">15",'tips dataset'!G1:G244,"<25") -> 3.4607317 | I22: =H22/G22 -> 0.1814743 | J22: =SUMIFS('tips dataset'!$F$1:$F$244,'tips dataset'!$F$1:$F$244,">15",'tips dataset'!$F$1:$F$244,"<25") -> 2059.57 | K22: =$J22/SUM($J$22:$J$25) -> 0.43265823 | L22: =SUMIFS('tips dataset'!$G$1:$G$244,'tips dataset'!$F$1:$F$244,">15",'tips dataset'!$F$1:$F$244,"<25") -> 326.04 | M22: =$L22/SUM($L$22:$L$25) -> 0.44919609
A23: Thur | B23: 1083.33 | C23: Low | D23: <15$ | E23: =COUNTIF('tips dataset'!$F$1:$F$244,"<15") -> 79 | F23: =DashBoard!$E23/SUM(DashBoard!$E$22:$E$25) -> 0.32644628 | G23: =AVERAGEIF('tips dataset'!$F$1:$F$244,"<15",'tips dataset'!$F$1:$F$244) -> 11.461139 | H23: =AVERAGEIF('tips dataset'!$F$1:$F$244,"<15",'tips dataset'!$G$1:$G$244) -> 2.0508861 | I23: =H23/G23 -> 0.1789426 | J23: =SUMIF('tips dataset'!F1:F244,"<15",'tips dataset'!$F$1:$F$244) -> 905.43 | K23: =$J23/SUM($J$22:$J$25) -> 0.1902056 | L23: =SUMIF('tips dataset'!$F$1:$F$244,"<15",'tips dataset'!$G$1:$G$244) -> 162.02 | M23: =$L23/SUM($L$22:$L$25) -> 0.22322031
A24: Sun | B24: 1627.16 | C24: High | D24: 26$-35$ | E24: =COUNTIFS('tips dataset'!$F$1:$F$244,">25",'tips dataset'!$F$1:$F$244,"<35") -> 39 | F24: =DashBoard!$E24/SUM(DashBoard!$E$22:$E$25) -> 0.16115702 | G24: =AVERAGEIFS('tips dataset'!$F$1:$F$244,'tips dataset'!$F$1:$F$244,">25",'tips dataset'!F2:F245,"<35") -> 29.325526 | H24: =AVERAGEIFS('tips dataset'!$G$1:$G$244,'tips dataset'!$F$1:$F$244,">25",'tips dataset'!G2:G245,"<35") -> 4.217963 | I24: =H24/G24 -> 0.14383247 | J24: =SUMIFS('tips dataset'!$F$1:$F$244,'tips dataset'!$F$1:$F$244,">25",'tips dataset'!$F$1:$F$244,"<35") -> 1149.2 | K24: =$J24/SUM($J$22:$J$25) -> 0.24141488 | L24: =SUMIFS('tips dataset'!$G$1:$G$244,'tips dataset'!$F$1:$F$244,">25",'tips dataset'!$F$1:$F$244,"<35") -> 156.06 | M24: =$L24/SUM($L$22:$L$25) -> 0.21500902
A25: Sat | B25: 1778.4 | C25: Premium | D25: >35$ | E25: =COUNTIF('tips dataset'!$F$1:$F$244,">35") -> 16 | F25: =DashBoard!$E25/SUM(DashBoard!$E$22:$E$25) -> 0.066115702 | G25: =AVERAGEIF('tips dataset'!$F$1:$F$244,">35",'tips dataset'!$F$1:$F$244) -> 42.223125 | H25: =AVERAGEIF('tips dataset'!$F$1:$F$244,">35",'tips dataset'!$G$1:$G$244) -> 5.106875 | I25: =H25/G25 -> 0.12094972 | J25: =SUMIF('tips dataset'!F3:F246,">35",'tips dataset'!$F$1:$F$244) -> 646.07 | K25: =$J25/SUM($J$22:$J$25) -> 0.13572129 | L25: =SUMIF('tips dataset'!$F$1:$F$244,">35",'tips dataset'!$G$1:$G$244) -> 81.71 | M25: =$L25/SUM($L$22:$L$25) -> 0.11257457

Sheet Executive Summary
A2: Executive summary
A4: Key Findings
A6: 1. Total Bill is strongest predictor of Tip (r = 0.675)
A7: 2. Dinner customers tip more than lunch customers
A8: Time | B8: Sum of tip
A9: Dinner | B9: 546.07
A10: Lunch | B10: 183.51
A15: 3. Saturday generates highest revenue
A16: Time | B16: Sum of total_bill
A17: Sat | B17: 1778.4
A18: Sun | B18: 1627.16
A19: Thur | B19: 1083.33
A20: Fri | B20: 325.88
A25: 4. On sat and sun customers vistited rest only during dinner
A27: Time | B27: Count of size
A28: Sat
A29: Dinner | B29: 1
A30: Sun
A31: Dinner | B31: 1
A32: Thur
A33: Dinner | B33: 0.016393443
A34: Lunch | B34: 0.98360656
A35: Fri
A36: Lunch | B36: 0.36842105
A37: Dinner | B37: 0.63157895
A38: 5.On thur about 98% of customers visit were during Lunch time
A40: 6.Smoking is not statistically significant
A41: Because smoker and non smokers Produce almost equal bills per customer and also they tip almost equally
F42: smoker | G42: Total revenue | H42: Count of smoker | I42: Bill Per person
F43: No | G43: 2897.43 | H43: 151 | I43: =G43/H43 -> 19.188278
F44: Yes | G44: 1917.34 | H44: 92 | I44: =G44/H44 -> 20.840652
F46: smoker | G46: Total tip | H46: % Tip | I46: Per person tip
F47: No | G47: 451.77 | H47: =G47/G43 -> 0.15592094 | I47: =G47/H43 -> 2.9918543
F48: Yes | G48: 277.81 | H48: =G48/G44 -> 0.14489345 | I48: =G48/H44 -> 3.0196739
A52: 7 Gender has no significant impact | D52: Sex | E52: Sum of total_bill | F52: Sum of tip | G52: Count by Sex | H52: Per person Bill By Gnder | I52: Tip By Gender
D53: Female | E53: 1557.95 | F53: 244.51 | G53: 86 | H53: =E53/G53 -> 18.115698 | I53: =F53/G53 -> 2.8431395
D54: Male | E54: 3256.82 | F54: 485.07 | G54: 157 | H54: =E54/G54 -> 20.744076 | I54: =F54/G54 -> 3.0896178
D55: Sex | E55: Sum of tip | F55: Sum of total_bill | G55: Tip % of total bill
D56: Female | E56: 244.51 | F56: 1557.95 | G56: =E56/F56 -> 0.15694342
D57: Male | E57: 485.07 | F57: 3256.82 | G57: =E57/F57 -> 0.14893976
...
